Workbook

Sheet Tools
A2: EoC Check
A3: Choose Date | B3: 46098
A4: Departure Airport Code | B4: lcy
A5: Arrival Airport Code | B5: ber | AB5: =IFERROR(__xludf.DUMMYFUNCTION("ifna(FILTER('EOC DB'!B3:C2875,'EOC DB'!A3:A2875=$B$3),ifna(ifna(FILTER('EOC DB'!F2:G2875,'EOC DB'!E2:E2875=VLOOKUP(B4,'Airports DB'!B1:E2875,3,0),$B$3>'EOC DB'!D2:D2875),ifna(FILTER('EOC DB'!K2:L2875,'EOC DB'!H2:H2875=$B$3&VLOOKUP(B4,'Airports DB'!B1:E287"&"5,3,0)),FILTER('EOC DB'!P2:Q2875,'EOC DB'!M2:M2875=$B$3&B4))),""No Extra Ordinary Circumstances""))"),"No Extra Ordinary Circumstances") -> No Extra Ordinary Circumstances
A6: Eligibility Check | B6: =IF(AB16+AK16=2,"Under EC 261/2004",if(AB16=1,"Under EC 261/2004",IF(AK16=1,"Please check the airline if the operator is an EU airline then it's under EC 261/2004","Not Under EC 261/2004"))) -> Under EC 261/2004 | AB6: =IFERROR(__xludf.DUMMYFUNCTION("ifna(FILTER('EOC DB'!B4:C2875,'EOC DB'!A4:A2875=$B$3),ifna(ifna(FILTER('EOC DB'!F3:G2875,'EOC DB'!E3:E2875=VLOOKUP(B5,'Airports DB'!B2:E2875,3,0),$B$3>'EOC DB'!D3:D2875),ifna(FILTER('EOC DB'!K3:L2875,'EOC DB'!H3:H2875=$B$3&VLOOKUP(B5,'Airports DB'!B2:E287"&"5,3,0)),FILTER('EOC DB'!P3:Q2875,'EOC DB'!M3:M2875=$B$3&B5))),""No Extra Ordinary Circumstances""))"),"No Extra Ordinary Circumstances") -> No Extra Ordinary Circumstances
A7: Notes | B7: =ifna(ifna("- Departure Country (" &VLOOKUP(AB26,'Countries DB'!$G:$G,1,0)&") is under EC261/2004","- Departure country ("&AB26&") Is Not under EC261")&" " &ifna("- Destination Country (" &VLOOKUP(AK26,'Countries DB'!$G:$G,1,0)&") is under EC261/2004","- Destination Country ("&AK26&") Is Not under EC261"),"") -> - Departure Country (United Kingdom) is under EC261/2004 - Destination Country (Germany) is under EC261/2004
A8: EoC Check | B8: =IF(AC5="reject","Reject Because "&B4&" airport had an EoC: "&AB5,IF(AC6="reject","Reject Because "&B5&" airport had an EoC: "&AB6,"No Extra Ordinary Circumstances")) -> No Extra Ordinary Circumstances
A13: Airlines Data
A14: Airline Name | B14: Air New Zealand (NZ)
A15: {=TRANSPOSE('Airline DB'!B1:H1)} | B15: =IFERROR(__xludf.DUMMYFUNCTION("TRANSPOSE(FILTER('Airline DB'!B:J,'Airline DB'!A:A=$B$14))"),"") | AK15: Des
A16: MAIN E-MAIL | B16: =IFERROR(__xludf.DUMMYFUNCTION("""COMPUTED_VALUE"""),"cro@airnz.co.nz") -> cro@airnz.co.nz | AB16: =IF(IFERROR(FIND("Not",AB19,1),1)=1,1,0) -> 1 | AK16: =IF(IFERROR(FIND("Not",AK19,1),1)=1,1,0) -> 1
A17: WAY OF SUBMISSION
A18: ( Links/ webform) | B18: =IFERROR(__xludf.DUMMYFUNCTION("""COMPUTED_VALUE"""),"https://www.airnewzealand.co.nz/feedback/complaint/") -> https://www.airnewzealand.co.nz/feedback/complaint/
A19: Mandatory | AB19: =ifna("Departure Country (" &VLOOKUP(AB26,'Countries DB'!$G:$G,1,0)&") is under EC261/2004","Departure country ("&AB26&") Is Not under EC261") -> Departure Country (United Kingdom) is under EC261/2004 | AK19: =ifna("Destination Country (" &VLOOKUP(AK26,'Countries DB'!$G:$G,1,0)&") is under EC261/2004","Destination Country ("&AK26&") Is Not under EC261") -> Destination Country (Germany) is under EC261/2004
A20: Other Links/ Address
A21: Remarks
A23: Jurisdictions
A24: Jurisdictions | B24: Romania
A25: RANK | B25: =IFERROR(__xludf.DUMMYFUNCTION("TRANSPOSE(FILTER(JR!O:W,JR!A:A=$B$24))"),2.0) -> 2
A26: EXPIRATION PERIOD | B26: =IFERROR(__xludf.DUMMYFUNCTION("""COMPUTED_VALUE"""),"3 years") -> 3 years | AB26: =VLOOKUP(Tools!B4,'Airports DB'!B1:D2875,3,0) -> United Kingdom | AC26: =IFERROR(__xludf.DUMMYFUNCTION("FILTER('Airports DB'!A1:F2875,'Airports DB'!D1:D2875=AB26)"),"Aberdeen") -> Aberdeen | AD26: =IFERROR(__xludf.DUMMYFUNCTION("""COMPUTED_VALUE"""),"ABZ") -> ABZ | AE26: =IFERROR(__xludf.DUMMYFUNCTION("""COMPUTED_VALUE"""),"Dyce") -> Dyce | AF26: =IFERROR(__xludf.DUMMYFUNCTION("""COMPUTED_VALUE"""),"United Kingdom") -> United Kingdom | AK26: =VLOOKUP(Tools!B5,'Airports DB'!B1:D2875,3,0) -> Germany | AL26: =IFERROR(__xludf.DUMMYFUNCTION("FILTER('Airports DB'!A1:F2875,'Airports DB'!D1:D2875=AK26)"),"Aachen") -> Aachen | AM26: =IFERROR(__xludf.DUMMYFUNCTION("""COMPUTED_VALUE"""),"AAH") -> AAH | AN26: =IFERROR(__xludf.DUMMYFUNCTION("""COMPUTED_VALUE"""),"Aachen/Merzbruck") -> Aachen/Merzbruck | AO26: =IFERROR(__xludf.DUMMYFUNCTION("""COMPUTED_VALUE"""),"Germany") -> Germany
A27: Assignment Form / POA | B27: =IFERROR(__xludf.DUMMYFUNCTION("""COMPUTED_VALUE"""),"Yes") -> Yes | AC27: =IFERROR(__xludf.DUMMYFUNCTION("""COMPUTED_VALUE"""),"Abingdon") -> Abingdon | AD27: =IFERROR(__xludf.DUMMYFUNCTION("""COMPUTED_VALUE"""),"ABB") -> ABB | AE27: =IFERROR(__xludf.DUMMYFUNCTION("""COMPUTED_VALUE"""),"RAF Station") -> RAF Station | AF27: =IFERROR(__xludf.DUMMYFUNCTION("""COMPUTED_VALUE"""),"United Kingdom") -> United Kingdom | AL27: =IFERROR(__xludf.DUMMYFUNCTION("""COMPUTED_VALUE"""),"Aachen") -> Aachen | AM27: =IFERROR(__xludf.DUMMYFUNCTION("""COMPUTED_VALUE"""),"ZIU") -> ZIU | AN27: =IFERROR(__xludf.DUMMYFUNCTION("""COMPUTED_VALUE"""),"Railway") -> Railway | AO27: =IFERROR(__xludf.DUMMYFUNCTION("""COMPUTED_VALUE"""),"Germany") -> Germany
A28: TKT/ BP | B28: =IFERROR(__xludf.DUMMYFUNCTION("""COMPUTED_VALUE"""),"Yes") -> Yes | AC28: =IFERROR(__xludf.DUMMYFUNCTION("""COMPUTED_VALUE"""),"Alconbury") -> Alconbury | AD28: =IFERROR(__xludf.DUMMYFUNCTION("""COMPUTED_VALUE"""),"AYH") -> AYH | AE28: =IFERROR(__xludf.DUMMYFUNCTION("""COMPUTED_VALUE"""),"RAF Station") -> RAF Station | AF28: =IFERROR(__xludf.DUMMYFUNCTION("""COMPUTED_VALUE"""),"United Kingdom") -> United Kingdom | AL28: =IFERROR(__xludf.DUMMYFUNCTION("""COMPUTED_VALUE"""),"Aix La Chapelle") -> Aix La Chapelle | AM28: =IFERROR(__xludf.DUMMYFUNCTION("""COMPUTED_VALUE"""),"XHJ") -> XHJ | AN28: =IFERROR(__xludf.DUMMYFUNCTION("""COMPUTED_VALUE"""),"Railway Station") -> Railway Station | AO28: =IFERROR(__xludf.DUMMYFUNCTION("""COMPUTED_VALUE"""),"Germany") -> Germany
A29: ID | B29: =IFERROR(__xludf.DUMMYFUNCTION("""COMPUTED_VALUE"""),"No") -> No | AC29: =IFERROR(__xludf.DUMMYFUNCTION("""COMPUTED_VALUE"""),"Alderney") -> Alderney | AD29: =IFERROR(__xludf.DUMMYFUNCTION("""COMPUTED_VALUE"""),"ACI") -> ACI | AE29: =IFERROR(__xludf.DUMMYFUNCTION("""COMPUTED_VALUE"""),"The Blaye") -> The Blaye | AF29: =IFERROR(__xludf.DUMMYFUNCTION("""COMPUTED_VALUE"""),"United Kingdom") -> United Kingdom | AL29: =IFERROR(__xludf.DUMMYFUNCTION("""COMPUTED_VALUE"""),"Altenburg") -> Altenburg | AM29: =IFERROR(__xludf.DUMMYFUNCTION("""COMPUTED_VALUE"""),"AOC") -> AOC | AN29: =IFERROR(__xludf.DUMMYFUNCTION("""COMPUTED_VALUE"""),"Altenburg Nobitz") -> Altenburg Nobitz | AO29: =IFERROR(__xludf.DUMMYFUNCTION("""COMPUTED_VALUE"""),"Germany") -> Germany
A30: Claim Email | B30: =IFERROR(__xludf.DUMMYFUNCTION("""COMPUTED_VALUE"""),"Yes") -> Yes | AC30: =IFERROR(__xludf.DUMMYFUNCTION("""COMPUTED_VALUE"""),"Andover") -> Andover | AD30: =IFERROR(__xludf.DUMMYFUNCTION("""COMPUTED_VALUE"""),"ADV") -> ADV | AE30: =IFERROR(__xludf.DUMMYFUNCTION("""COMPUTED_VALUE"""),"Andover") -> Andover | AF30: =IFERROR(__xludf.DUMMYFUNCTION("""COMPUTED_VALUE"""),"United Kingdom") -> United Kingdom | AL30: =IFERROR(__xludf.DUMMYFUNCTION("""COMPUTED_VALUE"""),"Aue") -> Aue | AM30: =IFERROR(__xludf.DUMMYFUNCTION("""COMPUTED_VALUE"""),"ZAU") -> ZAU | AN30: =IFERROR(__xludf.DUMMYFUNCTION("""COMPUTED_VALUE"""),"Sachsen Railway Stn.") -> Sachsen Railway Stn. | AO30: =IFERROR(__xludf.DUMMYFUNCTION("""COMPUTED_VALUE"""),"Germany") -> Germany
A31: Rerouted Tkt (missed leg) | B31: =IFERROR(__xludf.DUMMYFUNCTION("""COMPUTED_VALUE"""),"Yes") -> Yes | AC31: =IFERROR(__xludf.DUMMYFUNCTION("""COMPUTED_VALUE"""),"Bally Kelly") -> Bally Kelly | AD31: =IFERROR(__xludf.DUMMYFUNCTION("""COMPUTED_VALUE"""),"BOL") -> BOL | AE31: =IFERROR(__xludf.DUMMYFUNCTION("""COMPUTED_VALUE"""),"Bally Kelly") -> Bally Kelly | AF31: =IFERROR(__xludf.DUMMYFUNCTION("""COMPUTED_VALUE"""),"United Kingdom") -> United Kingdom | AL31: =IFERROR(__xludf.DUMMYFUNCTION("""COMPUTED_VALUE"""),"Baltrum") -> Baltrum | AM31: =IFERROR(__xludf.DUMMYFUNCTION("""COMPUTED_VALUE"""),"BMR") -> BMR | AN31: =IFERROR(__xludf.DUMMYFUNCTION("""COMPUTED_VALUE"""),"Baltrum") -> Baltrum | AO31: =IFERROR(__xludf.DUMMYFUNCTION("""COMPUTED_VALUE"""),"Germany") -> Germany
A32: Disruption Proof | B32: =IFERROR(__xludf.DUMMYFUNCTION("""COMPUTED_VALUE"""),"No") -> No | AC32: =IFERROR(__xludf.DUMMYFUNCTION("""COMPUTED_VALUE"""),"Barra") -> Barra | AD32: =IFERROR(__xludf.DUMMYFUNCTION("""COMPUTED_VALUE"""),"BRR") -> BRR | AE32: =IFERROR(__xludf.DUMMYFUNCTION("""COMPUTED_VALUE"""),"North Bay") -> North Bay | AF32: =IFERROR(__xludf.DUMMYFUNCTION("""COMPUTED_VALUE"""),"United Kingdom") -> United Kingdom | AL32: =IFERROR(__xludf.DUMMYFUNCTION("""COMPUTED_VALUE"""),"Barth") -> Barth | AM32: =IFERROR(__xludf.DUMMYFUNCTION("""COMPUTED_VALUE"""),"BBH") -> BBH | AN32: =IFERROR(__xludf.DUMMYFUNCTION("""COMPUTED_VALUE"""),"Barth") -> Barth | AO32: =IFERROR(__xludf.DUMMYFUNCTION("""COMPUTED_VALUE"""),"Germany") -> Germany
A33: Note | B33: =IFERROR(__xludf.DUMMYFUNCTION("""COMPUTED_VALUE"""),"Goal: 100 claims a week No legal assessment necessary: we should only check the disruption and EOC Documents required: AF, BP/eticket, claim, proof of sending the claim to airline") -> Goal: 100 claims a week No legal assessment necessary: we should only check the disruption and EOC Documents required: AF, BP/eticket, claim, proof of sending the claim to airline | AC33: =IFERROR(__xludf.DUMMYFUNCTION("""COMPUTED_VALUE"""),"Barrow-In-Furness") -> Barrow-In-Furness | AD33: =IFERROR(__xludf.DUMMYFUNCTION("""COMPUTED_VALUE"""),"BWF") -> BWF | AE33: =IFERROR(__xludf.DUMMYFUNCTION("""COMPUTED_VALUE"""),"Walney Island") -> Walney Island | AF33: =IFERROR(__xludf.DUMMYFUNCTION("""COMPUTED_VALUE"""),"United Kingdom") -> United Kingdom | AL33: =IFERROR(__xludf.DUMMYFUNCTION("""COMPUTED_VALUE"""),"Bayreuth") -> Bayreuth | AM33: =IFERROR(__xludf.DUMMYFUNCTION("""COMPUTED_VALUE"""),"BYU") -> BYU | AN33: =IFERROR(__xludf.DUMMYFUNCTION("""COMPUTED_VALUE"""),"Bindlacher-Berg") -> Bindlacher-Berg | AO33: =IFERROR(__xludf.DUMMYFUNCTION("""COMPUTED_VALUE"""),"Germany") -> Germany
AC34: =IFERROR(__xludf.DUMMYFUNCTION("""COMPUTED_VALUE"""),"Belfast") -> Belfast | AD34: =IFERROR(__xludf.DUMMYFUNCTION("""COMPUTED_VALUE"""),"BHD") -> BHD | AE34: =IFERROR(__xludf.DUMMYFUNCTION("""COMPUTED_VALUE"""),"Belfast City Airport") -> Belfast City Airport | AF34: =IFERROR(__xludf.DUMMYFUNCTION("""COMPUTED_VALUE"""),"United Kingdom") -> United Kingdom | AL34: =IFERROR(__xludf.DUMMYFUNCTION("""COMPUTED_VALUE"""),"Berlin") -> Berlin | AM34: =IFERROR(__xludf.DUMMYFUNCTION("""COMPUTED_VALUE"""),"QWC") -> QWC | AN34: =IFERROR(__xludf.DUMMYFUNCTION("""COMPUTED_VALUE"""),"Berlin Zoo") -> Berlin Zoo | AO34: =IFERROR(__xludf.DUMMYFUNCTION("""COMPUTED_VALUE"""),"Germany") -> Germany
AC35: =IFERROR(__xludf.DUMMYFUNCTION("""COMPUTED_VALUE"""),"Belfast") -> Belfast | AD35: =IFERROR(__xludf.DUMMYFUNCTION("""COMPUTED_VALUE"""),"BFS") -> BFS | AE35: =IFERROR(__xludf.DUMMYFUNCTION("""COMPUTED_VALUE"""),"Belfast Aldergrove International") -> Belfast Aldergrove International | AF35: =IFERROR(__xludf.DUMMYFUNCTION("""COMPUTED_VALUE"""),"United Kingdom") -> United Kingdom | AL35: =IFERROR(__xludf.DUMMYFUNCTION("""COMPUTED_VALUE"""),"Berlin") -> Berlin | AM35: =IFERROR(__xludf.DUMMYFUNCTION("""COMPUTED_VALUE"""),"GWW") -> GWW | AN35: =IFERROR(__xludf.DUMMYFUNCTION("""COMPUTED_VALUE"""),"RAF Gatow") -> RAF Gatow | AO35: =IFERROR(__xludf.DUMMYFUNCTION("""COMPUTED_VALUE"""),"Germany") -> Germany
AC36: =IFERROR(__xludf.DUMMYFUNCTION("""COMPUTED_VALUE"""),"Bembridge") -> Bembridge | AD36: =IFERROR(__xludf.DUMMYFUNCTION("""COMPUTED_VALUE"""),"BBP") -> BBP | AE36: =IFERROR(__xludf.DUMMYFUNCTION("""COMPUTED_VALUE"""),"Bembridge") -> Bembridge | AF36: =IFERROR(__xludf.DUMMYFUNCTION("""COMPUTED_VALUE"""),"United Kingdom") -> United Kingdom | AL36: =IFERROR(__xludf.DUMMYFUNCTION("""COMPUTED_VALUE"""),"Berlin") -> Berlin | AM36: =IFERROR(__xludf.DUMMYFUNCTION("""COMPUTED_VALUE"""),"SXF") -> SXF | AN36: =IFERROR(__xludf.DUMMYFUNCTION("""COMPUTED_VALUE"""),"Schoenefeld") -> Schoenefeld | AO36: =IFERROR(__xludf.DUMMYFUNCTION("""COMPUTED_VALUE"""),"Germany") -> Germany
AC37: =IFERROR(__xludf.DUMMYFUNCTION("""COMPUTED_VALUE"""),"Benbecula") -> Benbecula | AD37: =IFERROR(__xludf.DUMMYFUNCTION("""COMPUTED_VALUE"""),"BEB") -> BEB | AE37: =IFERROR(__xludf.DUMMYFUNCTION("""COMPUTED_VALUE"""),"Benbecula") -> Benbecula | AF37: =IFERROR(__xludf.DUMMYFUNCTION("""COMPUTED_VALUE"""),"United Kingdom") -> United Kingdom | AL37: =IFERROR(__xludf.DUMMYFUNCTION("""COMPUTED_VALUE"""),"Berlin") -> Berlin | AM37: =IFERROR(__xludf.DUMMYFUNCTION("""COMPUTED_VALUE"""),"TXL") -> TXL | AN37: =IFERROR(__xludf.DUMMYFUNCTION("""COMPUTED_VALUE"""),"Tegel") -> Tegel | AO37: =IFERROR(__xludf.DUMMYFUNCTION("""COMPUTED_VALUE"""),"Germany") -> Germany
AC38: =IFERROR(__xludf.DUMMYFUNCTION("""COMPUTED_VALUE"""),"Benson") -> Benson | AD38: =IFERROR(__xludf.DUMMYFUNCTION("""COMPUTED_VALUE"""),"BEX") -> BEX | AE38: =IFERROR(__xludf.DUMMYFUNCTION("""COMPUTED_VALUE"""),"RAF Station") -> RAF Station | AF38: =IFERROR(__xludf.DUMMYFUNCTION("""COMPUTED_VALUE"""),"United Kingdom") -> United Kingdom | AL38: =IFERROR(__xludf.DUMMYFUNCTION("""COMPUTED_VALUE"""),"Berlin") -> Berlin | AM38: =IFERROR(__xludf.DUMMYFUNCTION("""COMPUTED_VALUE"""),"THF") -> THF | AN38: =IFERROR(__xludf.DUMMYFUNCTION("""COMPUTED_VALUE"""),"Tempelhof") -> Tempelhof | AO38: =IFERROR(__xludf.DUMMYFUNCTION("""COMPUTED_VALUE"""),"Germany") -> Germany
AC39: =IFERROR(__xludf.DUMMYFUNCTION("""COMPUTED_VALUE"""),"Birmingham") -> Birmingham | AD39: =IFERROR(__xludf.DUMMYFUNCTION("""COMPUTED_VALUE"""),"ZBC") -> ZBC | AE39: =IFERROR(__xludf.DUMMYFUNCTION("""COMPUTED_VALUE"""),"Colmore Row Bus Stn") -> Colmore Row Bus Stn | AF39: =IFERROR(__xludf.DUMMYFUNCTION("""COMPUTED_VALUE"""),"United Kingdom") -> United Kingdom | AL39: =IFERROR(__xludf.DUMMYFUNCTION("""COMPUTED_VALUE"""),"Bielefeld") -> Bielefeld | AM39: =IFERROR(__xludf.DUMMYFUNCTION("""COMPUTED_VALUE"""),"BFE") -> BFE | AN39: =IFERROR(__xludf.DUMMYFUNCTION("""COMPUTED_VALUE"""),"Bielefeld") -> Bielefeld | AO39: =IFERROR(__xludf.DUMMYFUNCTION("""COMPUTED_VALUE"""),"Germany") -> Germany
AC40: =IFERROR(__xludf.DUMMYFUNCTION("""COMPUTED_VALUE"""),"Birmingham") -> Birmingham | AD40: =IFERROR(__xludf.DUMMYFUNCTION("""COMPUTED_VALUE"""),"BHX") -> BHX | AE40: =IFERROR(__xludf.DUMMYFUNCTION("""COMPUTED_VALUE"""),"Birmingham International") -> Birmingham International | AF40: =IFERROR(__xludf.DUMMYFUNCTION("""COMPUTED_VALUE"""),"United Kingdom") -> United Kingdom | AL40: =IFERROR(__xludf.DUMMYFUNCTION("""COMPUTED_VALUE"""),"Bitburg") -> Bitburg | AM40: =IFERROR(__xludf.DUMMYFUNCTION("""COMPUTED_VALUE"""),"BBJ") -> BBJ | AN40: =IFERROR(__xludf.DUMMYFUNCTION("""COMPUTED_VALUE"""),"Bitburg Air Base") -> Bitburg Air Base | AO40: =IFERROR(__xludf.DUMMYFUNCTION("""COMPUTED_VALUE"""),"Germany") -> Germany
AC41: =IFERROR(__xludf.DUMMYFUNCTION("""COMPUTED_VALUE"""),"Yateley") -> Yateley | AD41: =IFERROR(__xludf.DUMMYFUNCTION("""COMPUTED_VALUE"""),"BBS") -> BBS | AE41: =IFERROR(__xludf.DUMMYFUNCTION("""COMPUTED_VALUE"""),"Blackbushe") -> Blackbushe | AF41: =IFERROR(__xludf.DUMMYFUNCTION("""COMPUTED_VALUE"""),"United Kingdom") -> United Kingdom | AL41: =IFERROR(__xludf.DUMMYFUNCTION("""COMPUTED_VALUE"""),"Boeblingen") -> Boeblingen | AM41: =IFERROR(__xludf.DUMMYFUNCTION("""COMPUTED_VALUE"""),"PHM") -> PHM | AN41: =IFERROR(__xludf.DUMMYFUNCTION("""COMPUTED_VALUE"""),"Boeblingen") -> Boeblingen | AO41: =IFERROR(__xludf.DUMMYFUNCTION("""COMPUTED_VALUE"""),"Germany") -> Germany
AC42: =IFERROR(__xludf.DUMMYFUNCTION("""COMPUTED_VALUE"""),"Blackpool") -> Blackpool | AD42: =IFERROR(__xludf.DUMMYFUNCTION("""COMPUTED_VALUE"""),"BLK") -> BLK | AE42: =IFERROR(__xludf.DUMMYFUNCTION("""COMPUTED_VALUE"""),"Blackpool") -> Blackpool | AF42: =IFERROR(__xludf.DUMMYFUNCTION("""COMPUTED_VALUE"""),"United Kingdom") -> United Kingdom | AL42: =IFERROR(__xludf.DUMMYFUNCTION("""COMPUTED_VALUE"""),"Borkum") -> Borkum | AM42: =IFERROR(__xludf.DUMMYFUNCTION("""COMPUTED_VALUE"""),"BMK") -> BMK | AN42: =IFERROR(__xludf.DUMMYFUNCTION("""COMPUTED_VALUE"""),"Borkum") -> Borkum | AO42: =IFERROR(__xludf.DUMMYFUNCTION("""COMPUTED_VALUE"""),"Germany") -> Germany
AC43: =IFERROR(__xludf.DUMMYFUNCTION("""COMPUTED_VALUE"""),"Bournemouth") -> Bournemouth | AD43: =IFERROR(__xludf.DUMMYFUNCTION("""COMPUTED_VALUE"""),"BOH") -> BOH | AE43: =IFERROR(__xludf.DUMMYFUNCTION("""COMPUTED_VALUE"""),"Bournemouth International") -> Bournemouth International | AF43: =IFERROR(__xludf.DUMMYFUNCTION("""COMPUTED_VALUE"""),"United Kingdom") -> United Kingdom | AL43: =IFERROR(__xludf.DUMMYFUNCTION("""COMPUTED_VALUE"""),"Braunschweig") -> Braunschweig | AM43: =IFERROR(__xludf.DUMMYFUNCTION("""COMPUTED_VALUE"""),"BWE") -> BWE | AN43: =IFERROR(__xludf.DUMMYFUNCTION("""COMPUTED_VALUE"""),"Braunschweig") -> Braunschweig | AO43: =IFERROR(__xludf.DUMMYFUNCTION("""COMPUTED_VALUE"""),"Germany") -> Germany
AC44: =IFERROR(__xludf.DUMMYFUNCTION("""COMPUTED_VALUE"""),"Bradford") -> Bradford | AD44: =IFERROR(__xludf.DUMMYFUNCTION("""COMPUTED_VALUE"""),"BRF") -> BRF | AE44: =IFERROR(__xludf.DUMMYFUNCTION("""COMPUTED_VALUE"""),"Bradford") -> Bradford | AF44: =IFERROR(__xludf.DUMMYFUNCTION("""COMPUTED_VALUE"""),"United Kingdom") -> United Kingdom | AL44: =IFERROR(__xludf.DUMMYFUNCTION("""COMPUTED_VALUE"""),"Bremen") -> Bremen | AM44: =IFERROR(__xludf.DUMMYFUNCTION("""COMPUTED_VALUE"""),"BRE") -> BRE | AN44: =IFERROR(__xludf.DUMMYFUNCTION("""COMPUTED_VALUE"""),"Bremen") -> Bremen | AO44: =IFERROR(__xludf.DUMMYFUNCTION("""COMPUTED_VALUE"""),"Germany") -> Germany
AC45: =IFERROR(__xludf.DUMMYFUNCTION("""COMPUTED_VALUE"""),"Bradford") -> Bradford | AD45: =IFERROR(__xludf.DUMMYFUNCTION("""COMPUTED_VALUE"""),"ZFC") -> ZFC | AE45: =IFERROR(__xludf.DUMMYFUNCTION("""COMPUTED_VALUE"""),"Bus Station") -> Bus Station | AF45: =IFERROR(__xludf.DUMMYFUNCTION("""COMPUTED_VALUE"""),"United Kingdom") -> United Kingdom | AL45: =IFERROR(__xludf.DUMMYFUNCTION("""COMPUTED_VALUE"""),"Bremerhaven") -> Bremerhaven | AM45: =IFERROR(__xludf.DUMMYFUNCTION("""COMPUTED_VALUE"""),"BRV") -> BRV | AN45: =IFERROR(__xludf.DUMMYFUNCTION("""COMPUTED_VALUE"""),"Bremerhaven") -> Bremerhaven | AO45: =IFERROR(__xludf.DUMMYFUNCTION("""COMPUTED_VALUE"""),"Germany") -> Germany
AC46: =IFERROR(__xludf.DUMMYFUNCTION("""COMPUTED_VALUE"""),"Braintree") -> Braintree | AD46: =IFERROR(__xludf.DUMMYFUNCTION("""COMPUTED_VALUE"""),"WXF") -> WXF | AE46: =IFERROR(__xludf.DUMMYFUNCTION("""COMPUTED_VALUE"""),"Wether Fld RAF") -> Wether Fld RAF | AF46: =IFERROR(__xludf.DUMMYFUNCTION("""COMPUTED_VALUE"""),"United Kingdom") -> United Kingdom | AL46: =IFERROR(__xludf.DUMMYFUNCTION("""COMPUTED_VALUE"""),"Brueggen") -> Brueggen | AM46: =IFERROR(__xludf.DUMMYFUNCTION("""COMPUTED_VALUE"""),"BGN") -> BGN | AN46: =IFERROR(__xludf.DUMMYFUNCTION("""COMPUTED_VALUE"""),"R.A.F.") -> R.A.F. | AO46: =IFERROR(__xludf.DUMMYFUNCTION("""COMPUTED_VALUE"""),"Germany") -> Germany
...

Sheet JR
A1: =IFERROR(__xludf.DUMMYFUNCTION("IMPORTRANGE(""https://docs.google.com/spreadsheets/d/1vRztkEdMwazrjryEuxNBqxbQcg_cKEBuU59fnl4i3lI/edit?gid=1482188771#gid=1482188771"",""JURISDICTIONS!A:W"")"),"rff") -> rff | B1: =IFERROR(__xludf.DUMMYFUNCTION("""COMPUTED_VALUE"""),"Status") -> Status | C1: =IFERROR(__xludf.DUMMYFUNCTION("""COMPUTED_VALUE"""),"PROCESSING TIME") -> PROCESSING TIME | D1: =IFERROR(__xludf.DUMMYFUNCTION("""COMPUTED_VALUE"""),"JURISDICTION COSTS") -> JURISDICTION COSTS | E1: =IFERROR(__xludf.DUMMYFUNCTION("""COMPUTED_VALUE"""),"COURT FEES") -> COURT FEES | F1: =IFERROR(__xludf.DUMMYFUNCTION("""COMPUTED_VALUE"""),"LAWYER FEES") -> LAWYER FEES | G1: =IFERROR(__xludf.DUMMYFUNCTION("""COMPUTED_VALUE"""),"Lawyer 1") -> Lawyer 1 | H1: =IFERROR(__xludf.DUMMYFUNCTION("""COMPUTED_VALUE"""),"Lawyer 1 Contact") -> Lawyer 1 Contact | I1: =IFERROR(__xludf.DUMMYFUNCTION("""COMPUTED_VALUE"""),"Note") -> Note | J1: =IFERROR(__xludf.DUMMYFUNCTION("""COMPUTED_VALUE"""),"Lawyer 1 Sheet") -> Lawyer 1 Sheet | K1: =IFERROR(__xludf.DUMMYFUNCTION("""COMPUTED_VALUE"""),"Lawyer 2") -> Lawyer 2 | L1: =IFERROR(__xludf.DUMMYFUNCTION("""COMPUTED_VALUE"""),"Lawyer 2 Contact") -> Lawyer 2 Contact | M1: =IFERROR(__xludf.DUMMYFUNCTION("""COMPUTED_VALUE"""),"Lawyer 2 Claims") -> Lawyer 2 Claims | N1: =IFERROR(__xludf.DUMMYFUNCTION("""COMPUTED_VALUE"""),"Lawyer 2 Sheet") -> Lawyer 2 Sheet | O1: =IFERROR(__xludf.DUMMYFUNCTION("""COMPUTED_VALUE"""),"RANK") -> RANK | P1: =IFERROR(__xludf.DUMMYFUNCTION("""COMPUTED_VALUE"""),"EXPIRATION PERIOD") -> EXPIRATION PERIOD | Q1: =IFERROR(__xludf.DUMMYFUNCTION("""COMPUTED_VALUE"""),"Assignment Form / POA") -> Assignment Form / POA | R1: =IFERROR(__xludf.DUMMYFUNCTION("""COMPUTED_VALUE"""),"TKT/ BP") -> TKT/ BP | S1: =IFERROR(__xludf.DUMMYFUNCTION("""COMPUTED_VALUE"""),"ID") -> ID | T1: =IFERROR(__xludf.DUMMYFUNCTION("""COMPUTED_VALUE"""),"Claim Email") -> Claim Email | U1: =IFERROR(__xludf.DUMMYFUNCTION("""COMPUTED_VALUE"""),"Rerouted Tkt") -> Rerouted Tkt | V1: =IFERROR(__xludf.DUMMYFUNCTION("""COMPUTED_VALUE"""),"Disruption Proof") -> Disruption Proof | W1: =IFERROR(__xludf.DUMMYFUNCTION("""COMPUTED_VALUE"""),"Note") -> Note
A2: =IFERROR(__xludf.DUMMYFUNCTION("""COMPUTED_VALUE"""),"Sweden") -> Sweden | B2: =IFERROR(__xludf.DUMMYFUNCTION("""COMPUTED_VALUE"""),"CONTRACTED") -> CONTRACTED | C2: =IFERROR(__xludf.DUMMYFUNCTION("""COMPUTED_VALUE"""),"2–6 months") -> 2–6 months | G2: =IFERROR(__xludf.DUMMYFUNCTION("""COMPUTED_VALUE"""),"Michael Forvass") -> Michael Forvass | H2: =IFERROR(__xludf.DUMMYFUNCTION("""COMPUTED_VALUE"""),"michael@juristavdelningen.se") -> michael@juristavdelningen.se | J2: =IFERROR(__xludf.DUMMYFUNCTION("""COMPUTED_VALUE"""),"Sweden") -> Sweden | O2: =IFERROR(__xludf.DUMMYFUNCTION("""COMPUTED_VALUE"""),1.0) -> 1 | P2: =IFERROR(__xludf.DUMMYFUNCTION("""COMPUTED_VALUE"""),"2 months - 10 years") -> 2 months - 10 years | Q2: =IFERROR(__xludf.DUMMYFUNCTION("""COMPUTED_VALUE"""),"Yes") -> Yes | R2: =IFERROR(__xludf.DUMMYFUNCTION("""COMPUTED_VALUE"""),"Yes") -> Yes | S2: =IFERROR(__xludf.DUMMYFUNCTION("""COMPUTED_VALUE"""),"No") -> No | T2: =IFERROR(__xludf.DUMMYFUNCTION("""COMPUTED_VALUE"""),"Yes") -> Yes | U2: =IFERROR(__xludf.DUMMYFUNCTION("""COMPUTED_VALUE"""),"No") -> No | V2: =IFERROR(__xludf.DUMMYFUNCTION("""COMPUTED_VALUE"""),"No") -> No | W2: =IFERROR(__xludf.DUMMYFUNCTION("""COMPUTED_VALUE"""),"If a passenger notifies an airline within the first 2 months after a flight disruption, the claim should be eligible for 10 years.") -> If a passenger notifies an airline within the first 2 months after a flight disruption, the claim should be eligible for 10 years.
A3: =IFERROR(__xludf.DUMMYFUNCTION("""COMPUTED_VALUE"""),"Romania") -> Romania | B3: =IFERROR(__xludf.DUMMYFUNCTION("""COMPUTED_VALUE"""),"CONTRACTED") -> CONTRACTED | C3: =IFERROR(__xludf.DUMMYFUNCTION("""COMPUTED_VALUE"""),"Long") -> Long | G3: =IFERROR(__xludf.DUMMYFUNCTION("""COMPUTED_VALUE"""),"BOGDAN BLAJ") -> BOGDAN BLAJ | H3: =IFERROR(__xludf.DUMMYFUNCTION("""COMPUTED_VALUE"""),"bogdan@blaj-law.ro") -> bogdan@blaj-law.ro | J3: =IFERROR(__xludf.DUMMYFUNCTION("""COMPUTED_VALUE"""),"Romania") -> Romania | O3: =IFERROR(__xludf.DUMMYFUNCTION("""COMPUTED_VALUE"""),2.0) -> 2 | P3: =IFERROR(__xludf.DUMMYFUNCTION("""COMPUTED_VALUE"""),"3 years") -> 3 years | Q3: =IFERROR(__xludf.DUMMYFUNCTION("""COMPUTED_VALUE"""),"Yes") -> Yes | R3: =IFERROR(__xludf.DUMMYFUNCTION("""COMPUTED_VALUE"""),"Yes") -> Yes | S3: =IFERROR(__xludf.DUMMYFUNCTION("""COMPUTED_VALUE"""),"No") -> No | T3: =IFERROR(__xludf.DUMMYFUNCTION("""COMPUTED_VALUE"""),"Yes") -> Yes | U3: =IFERROR(__xludf.DUMMYFUNCTION("""COMPUTED_VALUE"""),"Yes") -> Yes | V3: =IFERROR(__xludf.DUMMYFUNCTION("""COMPUTED_VALUE"""),"No") -> No | W3: =IFERROR(__xludf.DUMMYFUNCTION("""COMPUTED_VALUE"""),"Goal: 100 claims a week No legal assessment necessary: we should only check the disruption and EOC Documents required: AF, BP/eticket, claim, proof of sending the claim to airline") -> Goal: 100 claims a week No legal assessment necessary: we should only check the disruption and EOC Documents required: AF, BP/eticket, claim, proof of sending the claim to airline
A4: =IFERROR(__xludf.DUMMYFUNCTION("""COMPUTED_VALUE"""),"Austria") -> Austria | B4: =IFERROR(__xludf.DUMMYFUNCTION("""COMPUTED_VALUE"""),"CONTRACTED") -> CONTRACTED | C4: =IFERROR(__xludf.DUMMYFUNCTION("""COMPUTED_VALUE"""),"2-6 months") -> 2-6 months | D4: =IFERROR(__xludf.DUMMYFUNCTION("""COMPUTED_VALUE"""),"attorney fees prescribed by the law") -> attorney fees prescribed by the law | E4: =IFERROR(__xludf.DUMMYFUNCTION("""COMPUTED_VALUE"""),"200 Euros: 70,00 EUR 400 Euro: 90,00 EUR 600 Euros: 90,00 EUR") -> 200 Euros: 70,00 EUR 400 Euro: 90,00 EUR 600 Euros: 90,00 EUR | F4: =IFERROR(__xludf.DUMMYFUNCTION("""COMPUTED_VALUE"""),"Between 2000-3000 EUR depending on the lawyer's workload") -> Between 2000-3000 EUR depending on the lawyer's workload | G4: =IFERROR(__xludf.DUMMYFUNCTION("""COMPUTED_VALUE"""),"ALEXANDER SKRIBE") -> ALEXANDER SKRIBE | H4: =IFERROR(__xludf.DUMMYFUNCTION("""COMPUTED_VALUE"""),"skribe@skribe.law - mader@skribe.law") -> skribe@skribe.law - mader@skribe.law | J4: =IFERROR(__xludf.DUMMYFUNCTION("""COMPUTED_VALUE"""),"Austria") -> Austria | O4: =IFERROR(__xludf.DUMMYFUNCTION("""COMPUTED_VALUE"""),3.0) -> 3 | P4: =IFERROR(__xludf.DUMMYFUNCTION("""COMPUTED_VALUE"""),"3 years") -> 3 years | Q4: =IFERROR(__xludf.DUMMYFUNCTION("""COMPUTED_VALUE"""),"Yes") -> Yes | R4: =IFERROR(__xludf.DUMMYFUNCTION("""COMPUTED_VALUE"""),"Yes") -> Yes | S4: =IFERROR(__xludf.DUMMYFUNCTION("""COMPUTED_VALUE"""),"Yes") -> Yes | T4: =IFERROR(__xludf.DUMMYFUNCTION("""COMPUTED_VALUE"""),"No") -> No | U4: =IFERROR(__xludf.DUMMYFUNCTION("""COMPUTED_VALUE"""),"Yes") -> Yes | V4: =IFERROR(__xludf.DUMMYFUNCTION("""COMPUTED_VALUE"""),"No") -> No
A5: =IFERROR(__xludf.DUMMYFUNCTION("""COMPUTED_VALUE"""),"France") -> France | B5: =IFERROR(__xludf.DUMMYFUNCTION("""COMPUTED_VALUE"""),"CONTRACTED") -> CONTRACTED | C5: =IFERROR(__xludf.DUMMYFUNCTION("""COMPUTED_VALUE"""),"~1 year") -> ~1 year | E5: =IFERROR(__xludf.DUMMYFUNCTION("""COMPUTED_VALUE"""),"If representing the consumer no fees.If representing the company fee in amount of _____") -> If representing the consumer no fees.If representing the company fee in amount of _____ | F5: =IFERROR(__xludf.DUMMYFUNCTION("""COMPUTED_VALUE"""),"50 EUR paid upfront, reimbursement of 10% of legal fees, average legal fees 200 EUR") -> 50 EUR paid upfront, reimbursement of 10% of legal fees, average legal fees 200 EUR | G5: =IFERROR(__xludf.DUMMYFUNCTION("""COMPUTED_VALUE"""),"JOYCE PITCHER") -> JOYCE PITCHER | H5: =IFERROR(__xludf.DUMMYFUNCTION("""COMPUTED_VALUE"""),"joyce@pitcher-avocat.fr claire@justice.cool") -> joyce@pitcher-avocat.fr claire@justice.cool | I5: =IFERROR(__xludf.DUMMYFUNCTION("""COMPUTED_VALUE"""),"www.justice.cool abdelrahman@refly.org @yo123321") -> www.justice.cool abdelrahman@refly.org @yo123321 | J5: =IFERROR(__xludf.DUMMYFUNCTION("""COMPUTED_VALUE"""),"France") -> France | O5: =IFERROR(__xludf.DUMMYFUNCTION("""COMPUTED_VALUE"""),4.0) -> 4 | P5: =IFERROR(__xludf.DUMMYFUNCTION("""COMPUTED_VALUE"""),"5 years") -> 5 years | Q5: =IFERROR(__xludf.DUMMYFUNCTION("""COMPUTED_VALUE"""),"Yes") -> Yes | R5: =IFERROR(__xludf.DUMMYFUNCTION("""COMPUTED_VALUE"""),"Yes") -> Yes | S5: =IFERROR(__xludf.DUMMYFUNCTION("""COMPUTED_VALUE"""),"Yes") -> Yes | T5: =IFERROR(__xludf.DUMMYFUNCTION("""COMPUTED_VALUE"""),"Yes") -> Yes | U5: =IFERROR(__xludf.DUMMYFUNCTION("""COMPUTED_VALUE"""),"Yes") -> Yes | V5: =IFERROR(__xludf.DUMMYFUNCTION("""COMPUTED_VALUE"""),"Yes") -> Yes | W5: =IFERROR(__xludf.DUMMYFUNCTION("""COMPUTED_VALUE"""),"Weather Check") -> Weather Check
A6: =IFERROR(__xludf.DUMMYFUNCTION("""COMPUTED_VALUE"""),"Italy") -> Italy | B6: =IFERROR(__xludf.DUMMYFUNCTION("""COMPUTED_VALUE"""),"CONTRACTED") -> CONTRACTED | C6: =IFERROR(__xludf.DUMMYFUNCTION("""COMPUTED_VALUE"""),"~1 year") -> ~1 year | E6: =IFERROR(__xludf.DUMMYFUNCTION("""COMPUTED_VALUE"""),"for claims below 2000 EUR - no court fees,, bailif costs - 30-40 EUR") -> for claims below 2000 EUR - no court fees,, bailif costs - 30-40 EUR | G6: =IFERROR(__xludf.DUMMYFUNCTION("""COMPUTED_VALUE"""),"MICHELE TARQUINIO") -> MICHELE TARQUINIO | H6: =IFERROR(__xludf.DUMMYFUNCTION("""COMPUTED_VALUE"""),"m.tarquinio77@gmail.com") -> m.tarquinio77@gmail.com | I6: =IFERROR(__xludf.DUMMYFUNCTION("""COMPUTED_VALUE"""),"https://login.aruba.it/auth/realms/pec/protocol/openid-connect/auth tarquinio.lawyer.refly@pec.it Coesius10+") -> https://login.aruba.it/auth/realms/pec/protocol/openid-connect/auth tarquinio.lawyer.refly@pec.it Coesius10+ | J6: =IFERROR(__xludf.DUMMYFUNCTION("""COMPUTED_VALUE"""),"Italy Michele") -> Italy Michele | K6: =IFERROR(__xludf.DUMMYFUNCTION("""COMPUTED_VALUE"""),"Alan Breda") -> Alan Breda | L6: =IFERROR(__xludf.DUMMYFUNCTION("""COMPUTED_VALUE"""),"info@studiolegalebreda.com") -> info@studiolegalebreda.com | M6: =IFERROR(__xludf.DUMMYFUNCTION("""COMPUTED_VALUE"""),268.0) -> 268 | N6: =IFERROR(__xludf.DUMMYFUNCTION("""COMPUTED_VALUE"""),"Italy Alan Breda") -> Italy Alan Breda | O6: =IFERROR(__xludf.DUMMYFUNCTION("""COMPUTED_VALUE"""),5.0) -> 5 | P6: =IFERROR(__xludf.DUMMYFUNCTION("""COMPUTED_VALUE"""),"2 years") -> 2 years | Q6: =IFERROR(__xludf.DUMMYFUNCTION("""COMPUTED_VALUE"""),"Yes") -> Yes | R6: =IFERROR(__xludf.DUMMYFUNCTION("""COMPUTED_VALUE"""),"Yes") -> Yes | S6: =IFERROR(__xludf.DUMMYFUNCTION("""COMPUTED_VALUE"""),"Yes") -> Yes | T6: =IFERROR(__xludf.DUMMYFUNCTION("""COMPUTED_VALUE"""),"yes") -> yes | U6: =IFERROR(__xludf.DUMMYFUNCTION("""COMPUTED_VALUE"""),"Yes") -> Yes | V6: =IFERROR(__xludf.DUMMYFUNCTION("""COMPUTED_VALUE"""),"Yes") -> Yes | W6: =IFERROR(__xludf.DUMMYFUNCTION("""COMPUTED_VALUE"""),"Michele: Goal: 100 claims a week our main lawyer claims should be uploaded to him only if we've send the claim to the airline using his email -> after 30 days we can share it with him- ID of the passenger needed in all claims Friendly airlines: Iberia"&", Vueling, Air Europe, WizzAir - only check the disruption, EOC and weather. No airpor stats Pietro (NEW) Goal: 40 claims usual + 10 with no dep/arr in IT Airlines: WizzAir Malta, WizzAir Hungary, Air Europa, TAP, Iberia, Air Dolomiti, Vueling ID requ"&"ired ") -> Michele: Goal: 100 claims a week our main lawyer claims should be uploaded to him only if we've send the claim to the airline using his email -> after 30 days we can share it with him- ID of the passenger needed in all claims Friendly airlines: Iberia, Vueling, Air Europe, WizzAir - only check the disruption, EOC and weather. No airpor stats Pietro (NEW) Goal: 40 claims usual + 10 with no dep/arr in IT Airlines: WizzAir Malta, WizzAir Hungary, Air Europa, TAP, Iberia, Air Dolomiti, Vueling ID required
A7: =IFERROR(__xludf.DUMMYFUNCTION("""COMPUTED_VALUE"""),"Spain") -> Spain | B7: =IFERROR(__xludf.DUMMYFUNCTION("""COMPUTED_VALUE"""),"CONTRACTED") -> CONTRACTED | C7: =IFERROR(__xludf.DUMMYFUNCTION("""COMPUTED_VALUE"""),"2–6 months") -> 2–6 months | G7: =IFERROR(__xludf.DUMMYFUNCTION("""COMPUTED_VALUE"""),"MMMM.ES") -> MMMM.ES | H7: =IFERROR(__xludf.DUMMYFUNCTION("""COMPUTED_VALUE"""),"rcedron@mmmm.es") -> rcedron@mmmm.es | J7: =IFERROR(__xludf.DUMMYFUNCTION("""COMPUTED_VALUE"""),"Spain — MMMM.ES") -> Spain — MMMM.ES | K7: =IFERROR(__xludf.DUMMYFUNCTION("""COMPUTED_VALUE"""),"LUPICINIO") -> LUPICINIO | L7: =IFERROR(__xludf.DUMMYFUNCTION("""COMPUTED_VALUE"""),"rga@lupicinio.com") -> rga@lupicinio.com | O7: =IFERROR(__xludf.DUMMYFUNCTION("""COMPUTED_VALUE"""),6.0) -> 6 | P7: =IFERROR(__xludf.DUMMYFUNCTION("""COMPUTED_VALUE"""),"5 years") -> 5 years | Q7: =IFERROR(__xludf.DUMMYFUNCTION("""COMPUTED_VALUE"""),"Yes") -> Yes | R7: =IFERROR(__xludf.DUMMYFUNCTION("""COMPUTED_VALUE"""),"Yes") -> Yes | S7: =IFERROR(__xludf.DUMMYFUNCTION("""COMPUTED_VALUE"""),"Yes") -> Yes | T7: =IFERROR(__xludf.DUMMYFUNCTION("""COMPUTED_VALUE"""),"No") -> No | U7: =IFERROR(__xludf.DUMMYFUNCTION("""COMPUTED_VALUE"""),"Yes") -> Yes | V7: =IFERROR(__xludf.DUMMYFUNCTION("""COMPUTED_VALUE"""),"Yes") -> Yes | W7: =IFERROR(__xludf.DUMMYFUNCTION("""COMPUTED_VALUE"""),"- Weather Check - Family book or minors certificate if someone is under 18 years old. - Request E-ticket if BP doesn't have Full route, PNR, Full Name, Date - Unknown is not acceptable as disruption proof - Booking Ref should visible on BP,if not, we ne"&"ed to include the flight number and date on AF") -> - Weather Check - Family book or minors certificate if someone is under 18 years old. - Request E-ticket if BP doesn't have Full route, PNR, Full Name, Date - Unknown is not acceptable as disruption proof - Booking Ref should visible on BP,if not, we need to include the flight number and date on AF
A8: =IFERROR(__xludf.DUMMYFUNCTION("""COMPUTED_VALUE"""),"Poland") -> Poland | B8: =IFERROR(__xludf.DUMMYFUNCTION("""COMPUTED_VALUE"""),"CONTRACTED") -> CONTRACTED | C8: =IFERROR(__xludf.DUMMYFUNCTION("""COMPUTED_VALUE"""),"Long") -> Long | D8: =IFERROR(__xludf.DUMMYFUNCTION("""COMPUTED_VALUE"""),"200 pln/case paid upfront plus attorney fess") -> 200 pln/case paid upfront plus attorney fess | E8: =IFERROR(__xludf.DUMMYFUNCTION("""COMPUTED_VALUE"""),"500 PLN - 1500 PLN - 100 PLN 1500 PLN - 4000 PLN - 200 PLN") -> 500 PLN - 1500 PLN - 100 PLN 1500 PLN - 4000 PLN - 200 PLN | F8: =IFERROR(__xludf.DUMMYFUNCTION("""COMPUTED_VALUE"""),"500 PLN -1500 PLN - 180PLN/270 PLN 1500 PLN-5000 PLN 600PLN/900 PLN") -> 500 PLN -1500 PLN - 180PLN/270 PLN 1500 PLN-5000 PLN 600PLN/900 PLN | G8: =IFERROR(__xludf.DUMMYFUNCTION("""COMPUTED_VALUE"""),"Sylwia Janiszewska") -> Sylwia Janiszewska | H8: =IFERROR(__xludf.DUMMYFUNCTION("""COMPUTED_VALUE"""),"radcaprawny@sylwia-janiszewska.pl") -> radcaprawny@sylwia-janiszewska.pl | J8: =IFERROR(__xludf.DUMMYFUNCTION("""COMPUTED_VALUE"""),"Poland") -> Poland | O8: =IFERROR(__xludf.DUMMYFUNCTION("""COMPUTED_VALUE"""),7.0) -> 7 | P8: =IFERROR(__xludf.DUMMYFUNCTION("""COMPUTED_VALUE"""),"1 year") -> 1 year | Q8: =IFERROR(__xludf.DUMMYFUNCTION("""COMPUTED_VALUE"""),"Yes") -> Yes | R8: =IFERROR(__xludf.DUMMYFUNCTION("""COMPUTED_VALUE"""),"Yes") -> Yes | S8: =IFERROR(__xludf.DUMMYFUNCTION("""COMPUTED_VALUE"""),"No") -> No | T8: =IFERROR(__xludf.DUMMYFUNCTION("""COMPUTED_VALUE"""),"Yes") -> Yes | U8: =IFERROR(__xludf.DUMMYFUNCTION("""COMPUTED_VALUE"""),"Yes") -> Yes | V8: =IFERROR(__xludf.DUMMYFUNCTION("""COMPUTED_VALUE"""),"Yes") -> Yes | W8: =IFERROR(__xludf.DUMMYFUNCTION("""COMPUTED_VALUE"""),"New AF for Wizzair. New AF handsigned for Ryanair and LOT or all cases moved to court birth certificate for minors, marriage cert if needed ") -> New AF for Wizzair. New AF handsigned for Ryanair and LOT or all cases moved to court birth certificate for minors, marriage cert if needed
A9: =IFERROR(__xludf.DUMMYFUNCTION("""COMPUTED_VALUE"""),"United Kingdom") -> United Kingdom | B9: =IFERROR(__xludf.DUMMYFUNCTION("""COMPUTED_VALUE"""),"CONTRACTED") -> CONTRACTED | C9: =IFERROR(__xludf.DUMMYFUNCTION("""COMPUTED_VALUE"""),"2–6 months") -> 2–6 months | D9: =IFERROR(__xludf.DUMMYFUNCTION("""COMPUTED_VALUE"""),"15% of the collected sum or the recovearable costs depending what is higher") -> 15% of the collected sum or the recovearable costs depending what is higher | E9: =IFERROR(__xludf.DUMMYFUNCTION("""COMPUTED_VALUE"""),"£35 (recoverable)") -> £35 (recoverable) | F9: =IFERROR(__xludf.DUMMYFUNCTION("""COMPUTED_VALUE"""),"Claims up to £500 – Recoverable costs = £50 Claims between £500 - £1000 - Recoverable costs = £70 Claims between £1000 - £5000 - Recoverable costs = £80 Claims over £5000 - Recoverable costs = £100") -> Claims up to £500 – Recoverable costs = £50 Claims between £500 - £1000 - Recoverable costs = £70 Claims between £1000 - £5000 - Recoverable costs = £80 Claims over £5000 - Recoverable costs = £100 | G9: =IFERROR(__xludf.DUMMYFUNCTION("""COMPUTED_VALUE"""),"LOVETTS SOLICITORS") -> LOVETTS SOLICITORS | H9: =IFERROR(__xludf.DUMMYFUNCTION("""COMPUTED_VALUE"""),"AndrewD@lovetts.co.uk") -> AndrewD@lovetts.co.uk | I9: =IFERROR(__xludf.DUMMYFUNCTION("""COMPUTED_VALUE"""),"lovetts.co.uk https://casemanager.lovetts.co.uk/ ID: R880BASSANT PW: BASSANTNABIL ") -> lovetts.co.uk https://casemanager.lovetts.co.uk/ ID: R880BASSANT PW: BASSANTNABIL | J9: =IFERROR(__xludf.DUMMYFUNCTION("""COMPUTED_VALUE"""),"UK") -> UK | K9: =IFERROR(__xludf.DUMMYFUNCTION("""COMPUTED_VALUE"""),"Shergroup") -> Shergroup | L9: =IFERROR(__xludf.DUMMYFUNCTION("""COMPUTED_VALUE"""),"s-saluza@shergroup.com l-kirkham@shergroup.com") -> s-saluza@shergroup.com l-kirkham@shergroup.com | N9: =IFERROR(__xludf.DUMMYFUNCTION("""COMPUTED_VALUE"""),"Share group") -> Share group | O9: =IFERROR(__xludf.DUMMYFUNCTION("""COMPUTED_VALUE"""),8.0) -> 8 | P9: =IFERROR(__xludf.DUMMYFUNCTION("""COMPUTED_VALUE"""),"6 years") -> 6 years | Q9: =IFERROR(__xludf.DUMMYFUNCTION("""COMPUTED_VALUE"""),"Yes") -> Yes | R9: =IFERROR(__xludf.DUMMYFUNCTION("""COMPUTED_VALUE"""),"Yes") -> Yes | S9: =IFERROR(__xludf.DUMMYFUNCTION("""COMPUTED_VALUE"""),"No") -> No | T9: =IFERROR(__xludf.DUMMYFUNCTION("""COMPUTED_VALUE"""),"Yes") -> Yes | U9: =IFERROR(__xludf.DUMMYFUNCTION("""COMPUTED_VALUE"""),"Yes") -> Yes | V9: =IFERROR(__xludf.DUMMYFUNCTION("""COMPUTED_VALUE"""),"No") -> No | W9: =IFERROR(__xludf.DUMMYFUNCTION("""COMPUTED_VALUE"""),"- Lovetts: No Ajet - Share group:Needs ID/Passport, and disruption proof Send cases with risky airports status and weather ") -> - Lovetts: No Ajet - Share group:Needs ID/Passport, and disruption proof Send cases with risky airports status and weather
A10: =IFERROR(__xludf.DUMMYFUNCTION("""COMPUTED_VALUE"""),"Belgium") -> Belgium | B10: =IFERROR(__xludf.DUMMYFUNCTION("""COMPUTED_VALUE"""),"CONTRACTED") -> CONTRACTED | C10: =IFERROR(__xludf.DUMMYFUNCTION("""COMPUTED_VALUE"""),"2-6 months") -> 2-6 months | G10: =IFERROR(__xludf.DUMMYFUNCTION("""COMPUTED_VALUE"""),"David") -> David | H10: =IFERROR(__xludf.DUMMYFUNCTION("""COMPUTED_VALUE"""),"david@davidleys.com") -> david@davidleys.com | J10: =IFERROR(__xludf.DUMMYFUNCTION("""COMPUTED_VALUE"""),"Belgium") -> Belgium | O10: =IFERROR(__xludf.DUMMYFUNCTION("""COMPUTED_VALUE"""),9.0) -> 9 | P10: =IFERROR(__xludf.DUMMYFUNCTION("""COMPUTED_VALUE"""),"5 years") -> 5 years | Q10: =IFERROR(__xludf.DUMMYFUNCTION("""COMPUTED_VALUE"""),"Yes") -> Yes | R10: =IFERROR(__xludf.DUMMYFUNCTION("""COMPUTED_VALUE"""),"Yes") -> Yes | S10: =IFERROR(__xludf.DUMMYFUNCTION("""COMPUTED_VALUE"""),"Yes") -> Yes | T10: =IFERROR(__xludf.DUMMYFUNCTION("""COMPUTED_VALUE"""),"Yes") -> Yes | U10: =IFERROR(__xludf.DUMMYFUNCTION("""COMPUTED_VALUE"""),"Yes") -> Yes | V10: =IFERROR(__xludf.DUMMYFUNCTION("""COMPUTED_VALUE"""),"Yes") -> Yes
A11: =IFERROR(__xludf.DUMMYFUNCTION("""COMPUTED_VALUE"""),"Germany") -> Germany | B11: =IFERROR(__xludf.DUMMYFUNCTION("""COMPUTED_VALUE"""),"CONTRACTED") -> CONTRACTED | C11: =IFERROR(__xludf.DUMMYFUNCTION("""COMPUTED_VALUE"""),"~1 year") -> ~1 year | D11: =IFERROR(__xludf.DUMMYFUNCTION("""COMPUTED_VALUE"""),"250,00 EUR - 142,50 EUR 400,00 EUR - 142,50 EUR 600,00 EUR - 240,00 EUR") -> 250,00 EUR - 142,50 EUR 400,00 EUR - 142,50 EUR 600,00 EUR - 240,00 EUR | E11: =IFERROR(__xludf.DUMMYFUNCTION("""COMPUTED_VALUE"""),"250,00 EUR - 114,00 EUR 400,00 EUR - 114,00 EUR 600,00 EUR - 174,00 EUR ") -> 250,00 EUR - 114,00 EUR 400,00 EUR - 114,00 EUR 600,00 EUR - 174,00 EUR | F11: =IFERROR(__xludf.DUMMYFUNCTION("""COMPUTED_VALUE"""),"250,00 EUR - 142,50 EUR 400,00 EUR - 142,50 EUR 600,00 EUR - 240,00 EUR") -> 250,00 EUR - 142,50 EUR 400,00 EUR - 142,50 EUR 600,00 EUR - 240,00 EUR | G11: =IFERROR(__xludf.DUMMYFUNCTION("""COMPUTED_VALUE"""),"MORITZ DIEKMANN") -> MORITZ DIEKMANN | H11: =IFERROR(__xludf.DUMMYFUNCTION("""COMPUTED_VALUE"""),"moritz.diekmann@diekmann-rechtsanwaelte.de") -> moritz.diekmann@diekmann-rechtsanwaelte.de | J11: =IFERROR(__xludf.DUMMYFUNCTION("""COMPUTED_VALUE"""),"Germany") -> Germany | O11: =IFERROR(__xludf.DUMMYFUNCTION("""COMPUTED_VALUE"""),10.0) -> 10 | P11: =IFERROR(__xludf.DUMMYFUNCTION("""COMPUTED_VALUE"""),"3 years (The last day of the third year)") -> 3 years (The last day of the third year) | Q11: =IFERROR(__xludf.DUMMYFUNCTION("""COMPUTED_VALUE"""),"Yes") -> Yes | R11: =IFERROR(__xludf.DUMMYFUNCTION("""COMPUTED_VALUE"""),"Yes") -> Yes | S11: =IFERROR(__xludf.DUMMYFUNCTION("""COMPUTED_VALUE"""),"Yes") -> Yes | T11: =IFERROR(__xludf.DUMMYFUNCTION("""COMPUTED_VALUE"""),"Yes") -> Yes | U11: =IFERROR(__xludf.DUMMYFUNCTION("""COMPUTED_VALUE"""),"Yes") -> Yes | V11: =IFERROR(__xludf.DUMMYFUNCTION("""COMPUTED_VALUE"""),"No") -> No | W11: =IFERROR(__xludf.DUMMYFUNCTION("""COMPUTED_VALUE"""),"- Only for Non German - The limitation period expires on the last day of the third year (for example, the limitation period for a flight on 25/2/2016 expires on 31/12/2019).") -> - Only for Non German - The limitation period expires on the last day of the third year (for example, the limitation period for a flight on 25/2/2016 expires on 31/12/2019).
A12: =IFERROR(__xludf.DUMMYFUNCTION("""COMPUTED_VALUE"""),"Hungary") -> Hungary | B12: =IFERROR(__xludf.DUMMYFUNCTION("""COMPUTED_VALUE"""),"TEST PHASE") -> TEST PHASE | C12: =IFERROR(__xludf.DUMMYFUNCTION("""COMPUTED_VALUE"""),"Unknown") -> Unknown | G12: =IFERROR(__xludf.DUMMYFUNCTION("""COMPUTED_VALUE"""),"BOGLÁR SZERVATIUSZ") -> BOGLÁR SZERVATIUSZ | H12: =IFERROR(__xludf.DUMMYFUNCTION("""COMPUTED_VALUE"""),"b.szervatiusz@llf.hu") -> b.szervatiusz@llf.hu | J12: =IFERROR(__xludf.DUMMYFUNCTION("""COMPUTED_VALUE"""),"Hungary") -> Hungary | O12: =IFERROR(__xludf.DUMMYFUNCTION("""COMPUTED_VALUE"""),11.0) -> 11 | P12: =IFERROR(__xludf.DUMMYFUNCTION("""COMPUTED_VALUE"""),"2 years") -> 2 years | Q12: =IFERROR(__xludf.DUMMYFUNCTION("""COMPUTED_VALUE"""),"Yes") -> Yes | R12: =IFERROR(__xludf.DUMMYFUNCTION("""COMPUTED_VALUE"""),"Yes") -> Yes | S12: =IFERROR(__xludf.DUMMYFUNCTION("""COMPUTED_VALUE"""),"No") -> No | T12: =IFERROR(__xludf.DUMMYFUNCTION("""COMPUTED_VALUE"""),"No") -> No | U12: =IFERROR(__xludf.DUMMYFUNCTION("""COMPUTED_VALUE"""),"Yes") -> Yes | V12: =IFERROR(__xludf.DUMMYFUNCTION("""COMPUTED_VALUE"""),"Yes") -> Yes | W12: =IFERROR(__xludf.DUMMYFUNCTION("""COMPUTED_VALUE"""),"[NO RYANAIR!!!]") -> [NO RYANAIR!!!]
A13: =IFERROR(__xludf.DUMMYFUNCTION("""COMPUTED_VALUE"""),"Turkey") -> Turkey | B13: =IFERROR(__xludf.DUMMYFUNCTION("""COMPUTED_VALUE"""),"TEST PHASE") -> TEST PHASE | C13: =IFERROR(__xludf.DUMMYFUNCTION("""COMPUTED_VALUE"""),"8-10 months") -> 8-10 months | E13: =IFERROR(__xludf.DUMMYFUNCTION("""COMPUTED_VALUE"""),"220 Euros (discounted in bulks)") -> 220 Euros (discounted in bulks) | F13: =IFERROR(__xludf.DUMMYFUNCTION("""COMPUTED_VALUE"""),"arround 15% of won claims or fixed amount ") -> arround 15% of won claims or fixed amount | G13: =IFERROR(__xludf.DUMMYFUNCTION("""COMPUTED_VALUE"""),"EDA AKGUL") -> EDA AKGUL | H13: =IFERROR(__xludf.DUMMYFUNCTION("""COMPUTED_VALUE"""),"eda.akgul@erten.av.tr") -> eda.akgul@erten.av.tr | J13: =IFERROR(__xludf.DUMMYFUNCTION("""COMPUTED_VALUE"""),"Turkish Jurisdiction") -> Turkish Jurisdiction | O13: =IFERROR(__xludf.DUMMYFUNCTION("""COMPUTED_VALUE"""),12.0) -> 12 | P13: =IFERROR(__xludf.DUMMYFUNCTION("""COMPUTED_VALUE"""),"2 years") -> 2 years | Q13: =IFERROR(__xludf.DUMMYFUNCTION("""COMPUTED_VALUE"""),"Yes") -> Yes | R13: =IFERROR(__xludf.DUMMYFUNCTION("""COMPUTED_VALUE"""),"Yes") -> Yes | S13: =IFERROR(__xludf.DUMMYFUNCTION("""COMPUTED_VALUE"""),"Yes") -> Yes | T13: =IFERROR(__xludf.DUMMYFUNCTION("""COMPUTED_VALUE"""),"No") -> No | U13: =IFERROR(__xludf.DUMMYFUNCTION("""COMPUTED_VALUE"""),"Yes") -> Yes | V13: =IFERROR(__xludf.DUMMYFUNCTION("""COMPUTED_VALUE"""),"No") -> No
A14: =IFERROR(__xludf.DUMMYFUNCTION("""COMPUTED_VALUE"""),"Denmark") -> Denmark | B14: =IFERROR(__xludf.DUMMYFUNCTION("""COMPUTED_VALUE"""),"TEST PHASE") -> TEST PHASE | C14: =IFERROR(__xludf.DUMMYFUNCTION("""COMPUTED_VALUE"""),"2–6 months") -> 2–6 months | D14: =IFERROR(__xludf.DUMMYFUNCTION("""COMPUTED_VALUE"""),"15% of the collected sum") -> 15% of the collected sum | J14: =IFERROR(__xludf.DUMMYFUNCTION("""COMPUTED_VALUE"""),"Denmark") -> Denmark | O14: =IFERROR(__xludf.DUMMYFUNCTION("""COMPUTED_VALUE"""),13.0) -> 13 | P14: =IFERROR(__xludf.DUMMYFUNCTION("""COMPUTED_VALUE"""),"3 years") -> 3 years | Q14: =IFERROR(__xludf.DUMMYFUNCTION("""COMPUTED_VALUE"""),"Yes") -> Yes | R14: =IFERROR(__xludf.DUMMYFUNCTION("""COMPUTED_VALUE"""),"Yes") -> Yes | S14: =IFERROR(__xludf.DUMMYFUNCTION("""COMPUTED_VALUE"""),"No") -> No | T14: =IFERROR(__xludf.DUMMYFUNCTION("""COMPUTED_VALUE"""),"Yes") -> Yes | U14: =IFERROR(__xludf.DUMMYFUNCTION("""COMPUTED_VALUE"""),"Yes") -> Yes | V14: =IFERROR(__xludf.DUMMYFUNCTION("""COMPUTED_VALUE"""),"No") -> No
A15: =IFERROR(__xludf.DUMMYFUNCTION("""COMPUTED_VALUE"""),"Norway") -> Norway | B15: =IFERROR(__xludf.DUMMYFUNCTION("""COMPUTED_VALUE"""),"TEST PHASE") -> TEST PHASE | C15: =IFERROR(__xludf.DUMMYFUNCTION("""COMPUTED_VALUE"""),"2–6 months") -> 2–6 months | D15: =IFERROR(__xludf.DUMMYFUNCTION("""COMPUTED_VALUE"""),"15% of the collected sum") -> 15% of the collected sum | J15: =IFERROR(__xludf.DUMMYFUNCTION("""COMPUTED_VALUE"""),"Norway") -> Norway | O15: =IFERROR(__xludf.DUMMYFUNCTION("""COMPUTED_VALUE"""),14.0) -> 14 | P15: =IFERROR(__xludf.DUMMYFUNCTION("""COMPUTED_VALUE"""),"3 years (check exp. time?) ") -> 3 years (check exp. time?) | Q15: =IFERROR(__xludf.DUMMYFUNCTION("""COMPUTED_VALUE"""),"Yes") -> Yes | R15: =IFERROR(__xludf.DUMMYFUNCTION("""COMPUTED_VALUE"""),"Yes") -> Yes | S15: =IFERROR(__xludf.DUMMYFUNCTION("""COMPUTED_VALUE"""),"No") -> No | T15: =IFERROR(__xludf.DUMMYFUNCTION("""COMPUTED_VALUE"""),"Yes") -> Yes | U15: =IFERROR(__xludf.DUMMYFUNCTION("""COMPUTED_VALUE"""),"Yes") -> Yes | V15: =IFERROR(__xludf.DUMMYFUNCTION("""COMPUTED_VALUE"""),"No") -> No
A16: =IFERROR(__xludf.DUMMYFUNCTION("""COMPUTED_VALUE"""),"Finland") -> Finland | B16: =IFERROR(__xludf.DUMMYFUNCTION("""COMPUTED_VALUE"""),"NO LAWYER") -> NO LAWYER | O16: =IFERROR(__xludf.DUMMYFUNCTION("""COMPUTED_VALUE"""),15.0) -> 15 | P16: =IFERROR(__xludf.DUMMYFUNCTION("""COMPUTED_VALUE"""),"3 years") -> 3 years | Q16: =IFERROR(__xludf.DUMMYFUNCTION("""COMPUTED_VALUE"""),"Yes") -> Yes | R16: =IFERROR(__xludf.DUMMYFUNCTION("""COMPUTED_VALUE"""),"Yes") -> Yes | S16: =IFERROR(__xludf.DUMMYFUNCTION("""COMPUTED_VALUE"""),"No") -> No | T16: =IFERROR(__xludf.DUMMYFUNCTION("""COMPUTED_VALUE"""),"Yes") -> Yes | U16: =IFERROR(__xludf.DUMMYFUNCTION("""COMPUTED_VALUE"""),"Yes") -> Yes | V16: =IFERROR(__xludf.DUMMYFUNCTION("""COMPUTED_VALUE"""),"No") -> No
A17: =IFERROR(__xludf.DUMMYFUNCTION("""COMPUTED_VALUE"""),"Portugal") -> Portugal | B17: =IFERROR(__xludf.DUMMYFUNCTION("""COMPUTED_VALUE"""),"NO LAWYER") -> NO LAWYER | C17: =IFERROR(__xludf.DUMMYFUNCTION("""COMPUTED_VALUE"""),"2–6 months") -> 2–6 months | E17: =IFERROR(__xludf.DUMMYFUNCTION("""COMPUTED_VALUE"""),"claims up to 5000 EUR - 102 EUR, 5000 EUR-15000 EUR - 204 EUR") -> claims up to 5000 EUR - 102 EUR, 5000 EUR-15000 EUR - 204 EUR | G17: =IFERROR(__xludf.DUMMYFUNCTION("""COMPUTED_VALUE"""),"ANDRÉ FIALHO") -> ANDRÉ FIALHO | H17: =IFERROR(__xludf.DUMMYFUNCTION("""COMPUTED_VALUE"""),"andrefialho-20648l@adv.oa.pt") -> andrefialho-20648l@adv.oa.pt | J17: =IFERROR(__xludf.DUMMYFUNCTION("""COMPUTED_VALUE"""),"Portugal") -> Portugal | O17: =IFERROR(__xludf.DUMMYFUNCTION("""COMPUTED_VALUE"""),16.0) -> 16 | P17: =IFERROR(__xludf.DUMMYFUNCTION("""COMPUTED_VALUE"""),"2 years") -> 2 years | Q17: =IFERROR(__xludf.DUMMYFUNCTION("""COMPUTED_VALUE"""),"Yes") -> Yes | R17: =IFERROR(__xludf.DUMMYFUNCTION("""COMPUTED_VALUE"""),"Yes") -> Yes | S17: =IFERROR(__xludf.DUMMYFUNCTION("""COMPUTED_VALUE"""),"Yes (ID or TAX ID number)") -> Yes (ID or TAX ID number) | T17: =IFERROR(__xludf.DUMMYFUNCTION("""COMPUTED_VALUE"""),"Yes") -> Yes | U17: =IFERROR(__xludf.DUMMYFUNCTION("""COMPUTED_VALUE"""),"Yes") -> Yes | V17: =IFERROR(__xludf.DUMMYFUNCTION("""COMPUTED_VALUE"""),"Yes") -> Yes
A18: =IFERROR(__xludf.DUMMYFUNCTION("""COMPUTED_VALUE"""),"Netherlands") -> Netherlands | B18: =IFERROR(__xludf.DUMMYFUNCTION("""COMPUTED_VALUE"""),"ACTIVELY SEARCHING") -> ACTIVELY SEARCHING | E18: =IFERROR(__xludf.DUMMYFUNCTION("""COMPUTED_VALUE"""),"claims under 500 euro - € 130 claims between 500 and 1500 euro - € 328") -> claims under 500 euro - € 130 claims between 500 and 1500 euro - € 328 | O18: =IFERROR(__xludf.DUMMYFUNCTION("""COMPUTED_VALUE"""),17.0) -> 17 | P18: =IFERROR(__xludf.DUMMYFUNCTION("""COMPUTED_VALUE"""),"2 years") -> 2 years | Q18: =IFERROR(__xludf.DUMMYFUNCTION("""COMPUTED_VALUE"""),"Yes") -> Yes | R18: =IFERROR(__xludf.DUMMYFUNCTION("""COMPUTED_VALUE"""),"Yes") -> Yes | S18: =IFERROR(__xludf.DUMMYFUNCTION("""COMPUTED_VALUE"""),"Yes") -> Yes | T18: =IFERROR(__xludf.DUMMYFUNCTION("""COMPUTED_VALUE"""),"Yes") -> Yes | U18: =IFERROR(__xludf.DUMMYFUNCTION("""COMPUTED_VALUE"""),"Yes") -> Yes | V18: =IFERROR(__xludf.DUMMYFUNCTION("""COMPUTED_VALUE"""),"Yes") -> Yes
A19: =IFERROR(__xludf.DUMMYFUNCTION("""COMPUTED_VALUE"""),"Latvia") -> Latvia | B19: =IFERROR(__xludf.DUMMYFUNCTION("""COMPUTED_VALUE"""),"NO LAWYER") -> NO LAWYER | O19: =IFERROR(__xludf.DUMMYFUNCTION("""COMPUTED_VALUE"""),18.0) -> 18 | P19: =IFERROR(__xludf.DUMMYFUNCTION("""COMPUTED_VALUE"""),"1 year") -> 1 year | Q19: =IFERROR(__xludf.DUMMYFUNCTION("""COMPUTED_VALUE"""),"Yes") -> Yes | R19: =IFERROR(__xludf.DUMMYFUNCTION("""COMPUTED_VALUE"""),"Yes") -> Yes | S19: =IFERROR(__xludf.DUMMYFUNCTION("""COMPUTED_VALUE"""),"Yes (Wizz), other No") -> Yes (Wizz), other No | T19: =IFERROR(__xludf.DUMMYFUNCTION("""COMPUTED_VALUE"""),"Yes") -> Yes | U19: =IFERROR(__xludf.DUMMYFUNCTION("""COMPUTED_VALUE"""),"No") -> No | V19: =IFERROR(__xludf.DUMMYFUNCTION("""COMPUTED_VALUE"""),"Yes") -> Yes
A20: =IFERROR(__xludf.DUMMYFUNCTION("""COMPUTED_VALUE"""),"LITHUANIA") -> LITHUANIA | B20: =IFERROR(__xludf.DUMMYFUNCTION("""COMPUTED_VALUE"""),"NO LAWYER") -> NO LAWYER | O20: =IFERROR(__xludf.DUMMYFUNCTION("""COMPUTED_VALUE"""),19.0) -> 19 | P20: =IFERROR(__xludf.DUMMYFUNCTION("""COMPUTED_VALUE"""),"3 years") -> 3 years | Q20: =IFERROR(__xludf.DUMMYFUNCTION("""COMPUTED_VALUE"""),"Yes") -> Yes | R20: =IFERROR(__xludf.DUMMYFUNCTION("""COMPUTED_VALUE"""),"Yes") -> Yes | S20: =IFERROR(__xludf.DUMMYFUNCTION("""COMPUTED_VALUE"""),"Yes (Wizz), other No") -> Yes (Wizz), other No | T20: =IFERROR(__xludf.DUMMYFUNCTION("""COMPUTED_VALUE"""),"Yes") -> Yes | U20: =IFERROR(__xludf.DUMMYFUNCTION("""COMPUTED_VALUE"""),"No") -> No | V20: =IFERROR(__xludf.DUMMYFUNCTION("""COMPUTED_VALUE"""),"Yes") -> Yes
A21: =IFERROR(__xludf.DUMMYFUNCTION("""COMPUTED_VALUE"""),"ESTONIA") -> ESTONIA | B21: =IFERROR(__xludf.DUMMYFUNCTION("""COMPUTED_VALUE"""),"NO LAWYER") -> NO LAWYER | O21: =IFERROR(__xludf.DUMMYFUNCTION("""COMPUTED_VALUE"""),20.0) -> 20 | P21: =IFERROR(__xludf.DUMMYFUNCTION("""COMPUTED_VALUE"""),"3 years") -> 3 years | Q21: =IFERROR(__xludf.DUMMYFUNCTION("""COMPUTED_VALUE"""),"Yes") -> Yes | R21: =IFERROR(__xludf.DUMMYFUNCTION("""COMPUTED_VALUE"""),"Yes") -> Yes | S21: =IFERROR(__xludf.DUMMYFUNCTION("""COMPUTED_VALUE"""),"Yes (Wizz), other No") -> Yes (Wizz), other No | T21: =IFERROR(__xludf.DUMMYFUNCTION("""COMPUTED_VALUE"""),"Yes") -> Yes | U21: =IFERROR(__xludf.DUMMYFUNCTION("""COMPUTED_VALUE"""),"No") -> No | V21: =IFERROR(__xludf.DUMMYFUNCTION("""COMPUTED_VALUE"""),"Yes") -> Yes
A22: =IFERROR(__xludf.DUMMYFUNCTION("""COMPUTED_VALUE"""),"Ireland") -> Ireland | B22: =IFERROR(__xludf.DUMMYFUNCTION("""COMPUTED_VALUE"""),"NO LAWYER") -> NO LAWYER | O22: =IFERROR(__xludf.DUMMYFUNCTION("""COMPUTED_VALUE"""),21.0) -> 21 | P22: =IFERROR(__xludf.DUMMYFUNCTION("""COMPUTED_VALUE"""),"6 years") -> 6 years | Q22: =IFERROR(__xludf.DUMMYFUNCTION("""COMPUTED_VALUE"""),"Yes") -> Yes | R22: =IFERROR(__xludf.DUMMYFUNCTION("""COMPUTED_VALUE"""),"Yes") -> Yes | S22: =IFERROR(__xludf.DUMMYFUNCTION("""COMPUTED_VALUE"""),"Yes") -> Yes | T22: =IFERROR(__xludf.DUMMYFUNCTION("""COMPUTED_VALUE"""),"Yes") -> Yes | U22: =IFERROR(__xludf.DUMMYFUNCTION("""COMPUTED_VALUE"""),"Yes") -> Yes | V22: =IFERROR(__xludf.DUMMYFUNCTION("""COMPUTED_VALUE"""),"Yes") -> Yes
A23: =IFERROR(__xludf.DUMMYFUNCTION("""COMPUTED_VALUE"""),"GREECE") -> GREECE | B23: =IFERROR(__xludf.DUMMYFUNCTION("""COMPUTED_VALUE"""),"ACTIVELY SEARCHING") -> ACTIVELY SEARCHING | C23: =IFERROR(__xludf.DUMMYFUNCTION("""COMPUTED_VALUE"""),"up to 2 years") -> up to 2 years | O23: =IFERROR(__xludf.DUMMYFUNCTION("""COMPUTED_VALUE"""),22.0) -> 22 | P23: =IFERROR(__xludf.DUMMYFUNCTION("""COMPUTED_VALUE"""),"5 years") -> 5 years | Q23: =IFERROR(__xludf.DUMMYFUNCTION("""COMPUTED_VALUE"""),"Yes") -> Yes | R23: =IFERROR(__xludf.DUMMYFUNCTION("""COMPUTED_VALUE"""),"Yes") -> Yes | S23: =IFERROR(__xludf.DUMMYFUNCTION("""COMPUTED_VALUE"""),"Yes") -> Yes | T23: =IFERROR(__xludf.DUMMYFUNCTION("""COMPUTED_VALUE"""),"Yes") -> Yes | U23: =IFERROR(__xludf.DUMMYFUNCTION("""COMPUTED_VALUE"""),"Yes") -> Yes | V23: =IFERROR(__xludf.DUMMYFUNCTION("""COMPUTED_VALUE"""),"Yes") -> Yes
A24: =IFERROR(__xludf.DUMMYFUNCTION("""COMPUTED_VALUE"""),"BULGARIA") -> BULGARIA | B24: =IFERROR(__xludf.DUMMYFUNCTION("""COMPUTED_VALUE"""),"NO LAWYER") -> NO LAWYER | O24: =IFERROR(__xludf.DUMMYFUNCTION("""COMPUTED_VALUE"""),23.0) -> 23 | P24: =IFERROR(__xludf.DUMMYFUNCTION("""COMPUTED_VALUE"""),"1 year") -> 1 year | Q24: =IFERROR(__xludf.DUMMYFUNCTION("""COMPUTED_VALUE"""),"Yes") -> Yes | R24: =IFERROR(__xludf.DUMMYFUNCTION("""COMPUTED_VALUE"""),"Yes") -> Yes | S24: =IFERROR(__xludf.DUMMYFUNCTION("""COMPUTED_VALUE"""),"Yes") -> Yes | T24: =IFERROR(__xludf.DUMMYFUNCTION("""COMPUTED_VALUE"""),"No") -> No | U24: =IFERROR(__xludf.DUMMYFUNCTION("""COMPUTED_VALUE"""),"Yes") -> Yes | V24: =IFERROR(__xludf.DUMMYFUNCTION("""COMPUTED_VALUE"""),"Yes") -> Yes
A25: =IFERROR(__xludf.DUMMYFUNCTION("""COMPUTED_VALUE"""),"ALBANIA") -> ALBANIA | B25: =IFERROR(__xludf.DUMMYFUNCTION("""COMPUTED_VALUE"""),"NO LAWYER") -> NO LAWYER | O25: =IFERROR(__xludf.DUMMYFUNCTION("""COMPUTED_VALUE"""),24.0) -> 24 | P25: =IFERROR(__xludf.DUMMYFUNCTION("""COMPUTED_VALUE"""),"3 years") -> 3 years | Q25: =IFERROR(__xludf.DUMMYFUNCTION("""COMPUTED_VALUE"""),"Yes") -> Yes | R25: =IFERROR(__xludf.DUMMYFUNCTION("""COMPUTED_VALUE"""),"Yes") -> Yes | S25: =IFERROR(__xludf.DUMMYFUNCTION("""COMPUTED_VALUE"""),"Yes") -> Yes | T25: =IFERROR(__xludf.DUMMYFUNCTION("""COMPUTED_VALUE"""),"Yes") -> Yes | U25: =IFERROR(__xludf.DUMMYFUNCTION("""COMPUTED_VALUE"""),"Yes") -> Yes | V25: =IFERROR(__xludf.DUMMYFUNCTION("""COMPUTED_VALUE"""),"Yes") -> Yes
A26: =IFERROR(__xludf.DUMMYFUNCTION("""COMPUTED_VALUE"""),"Croatia") -> Croatia | B26: =IFERROR(__xludf.DUMMYFUNCTION("""COMPUTED_VALUE"""),"NO LAWYER") -> NO LAWYER | O26: =IFERROR(__xludf.DUMMYFUNCTION("""COMPUTED_VALUE"""),25.0) -> 25 | P26: =IFERROR(__xludf.DUMMYFUNCTION("""COMPUTED_VALUE"""),"3 years") -> 3 years | Q26: =IFERROR(__xludf.DUMMYFUNCTION("""COMPUTED_VALUE"""),"Yes") -> Yes | R26: =IFERROR(__xludf.DUMMYFUNCTION("""COMPUTED_VALUE"""),"Yes") -> Yes | S26: =IFERROR(__xludf.DUMMYFUNCTION("""COMPUTED_VALUE"""),"Yes") -> Yes | T26: =IFERROR(__xludf.DUMMYFUNCTION("""COMPUTED_VALUE"""),"Yes") -> Yes | U26: =IFERROR(__xludf.DUMMYFUNCTION("""COMPUTED_VALUE"""),"Yes") -> Yes | V26: =IFERROR(__xludf.DUMMYFUNCTION("""COMPUTED_VALUE"""),"Yes") -> Yes
A27: =IFERROR(__xludf.DUMMYFUNCTION("""COMPUTED_VALUE"""),"Cyprus") -> Cyprus | B27: =IFERROR(__xludf.DUMMYFUNCTION("""COMPUTED_VALUE"""),"NO LAWYER") -> NO LAWYER | O27: =IFERROR(__xludf.DUMMYFUNCTION("""COMPUTED_VALUE"""),26.0) -> 26 | P27: =IFERROR(__xludf.DUMMYFUNCTION("""COMPUTED_VALUE"""),"6 years") -> 6 years | Q27: =IFERROR(__xludf.DUMMYFUNCTION("""COMPUTED_VALUE"""),"Yes") -> Yes | R27: =IFERROR(__xludf.DUMMYFUNCTION("""COMPUTED_VALUE"""),"Yes") -> Yes | S27: =IFERROR(__xludf.DUMMYFUNCTION("""COMPUTED_VALUE"""),"Yes") -> Yes | T27: =IFERROR(__xludf.DUMMYFUNCTION("""COMPUTED_VALUE"""),"Yes") -> Yes | U27: =IFERROR(__xludf.DUMMYFUNCTION("""COMPUTED_VALUE"""),"Yes") -> Yes | V27: =IFERROR(__xludf.DUMMYFUNCTION("""COMPUTED_VALUE"""),"Yes") -> Yes
A28: =IFERROR(__xludf.DUMMYFUNCTION("""COMPUTED_VALUE"""),"Czech Republic") -> Czech Republic | B28: =IFERROR(__xludf.DUMMYFUNCTION("""COMPUTED_VALUE"""),"NO LAWYER") -> NO LAWYER | O28: =IFERROR(__xludf.DUMMYFUNCTION("""COMPUTED_VALUE"""),27.0) -> 27 | P28: =IFERROR(__xludf.DUMMYFUNCTION("""COMPUTED_VALUE"""),"6 Months - 3 years") -> 6 Months - 3 years | Q28: =IFERROR(__xludf.DUMMYFUNCTION("""COMPUTED_VALUE"""),"Yes") -> Yes | R28: =IFERROR(__xludf.DUMMYFUNCTION("""COMPUTED_VALUE"""),"Yes") -> Yes | S28: =IFERROR(__xludf.DUMMYFUNCTION("""COMPUTED_VALUE"""),"Yes") -> Yes | T28: =IFERROR(__xludf.DUMMYFUNCTION("""COMPUTED_VALUE"""),"Yes") -> Yes | U28: =IFERROR(__xludf.DUMMYFUNCTION("""COMPUTED_VALUE"""),"Yes") -> Yes | V28: =IFERROR(__xludf.DUMMYFUNCTION("""COMPUTED_VALUE"""),"Yes") -> Yes | W28: =IFERROR(__xludf.DUMMYFUNCTION("""COMPUTED_VALUE"""),"if a passenger notifies the airline within the first 6 months after flight disruption, the claim should be eligible for 3 years.") -> if a passenger notifies the airline within the first 6 months after flight disruption, the claim should be eligible for 3 years.
A29: =IFERROR(__xludf.DUMMYFUNCTION("""COMPUTED_VALUE"""),"Iceland") -> Iceland | B29: =IFERROR(__xludf.DUMMYFUNCTION("""COMPUTED_VALUE"""),"NO LAWYER") -> NO LAWYER | O29: =IFERROR(__xludf.DUMMYFUNCTION("""COMPUTED_VALUE"""),28.0) -> 28 | P29: =IFERROR(__xludf.DUMMYFUNCTION("""COMPUTED_VALUE"""),"2 years") -> 2 years | Q29: =IFERROR(__xludf.DUMMYFUNCTION("""COMPUTED_VALUE"""),"Yes") -> Yes | R29: =IFERROR(__xludf.DUMMYFUNCTION("""COMPUTED_VALUE"""),"Yes") -> Yes | S29: =IFERROR(__xludf.DUMMYFUNCTION("""COMPUTED_VALUE"""),"Yes") -> Yes | T29: =IFERROR(__xludf.DUMMYFUNCTION("""COMPUTED_VALUE"""),"Yes") -> Yes | U29: =IFERROR(__xludf.DUMMYFUNCTION("""COMPUTED_VALUE"""),"Yes") -> Yes | V29: =IFERROR(__xludf.DUMMYFUNCTION("""COMPUTED_VALUE"""),"Yes") -> Yes
A30: =IFERROR(__xludf.DUMMYFUNCTION("""COMPUTED_VALUE"""),"Luxembourg") -> Luxembourg | B30: =IFERROR(__xludf.DUMMYFUNCTION("""COMPUTED_VALUE"""),"NO LAWYER") -> NO LAWYER | O30: =IFERROR(__xludf.DUMMYFUNCTION("""COMPUTED_VALUE"""),29.0) -> 29 | P30: =IFERROR(__xludf.DUMMYFUNCTION("""COMPUTED_VALUE"""),"10 years") -> 10 years | Q30: =IFERROR(__xludf.DUMMYFUNCTION("""COMPUTED_VALUE"""),"Yes") -> Yes | R30: =IFERROR(__xludf.DUMMYFUNCTION("""COMPUTED_VALUE"""),"Yes") -> Yes | S30: =IFERROR(__xludf.DUMMYFUNCTION("""COMPUTED_VALUE"""),"Yes") -> Yes | T30: =IFERROR(__xludf.DUMMYFUNCTION("""COMPUTED_VALUE"""),"Yes") -> Yes | U30: =IFERROR(__xludf.DUMMYFUNCTION("""COMPUTED_VALUE"""),"Yes") -> Yes | V30: =IFERROR(__xludf.DUMMYFUNCTION("""COMPUTED_VALUE"""),"Yes") -> Yes
A31: =IFERROR(__xludf.DUMMYFUNCTION("""COMPUTED_VALUE"""),"Malta") -> Malta | B31: =IFERROR(__xludf.DUMMYFUNCTION("""COMPUTED_VALUE"""),"NO LAWYER") -> NO LAWYER | O31: =IFERROR(__xludf.DUMMYFUNCTION("""COMPUTED_VALUE"""),30.0) -> 30 | P31: =IFERROR(__xludf.DUMMYFUNCTION("""COMPUTED_VALUE"""),"No limit") -> No limit | Q31: =IFERROR(__xludf.DUMMYFUNCTION("""COMPUTED_VALUE"""),"Yes") -> Yes | R31: =IFERROR(__xludf.DUMMYFUNCTION("""COMPUTED_VALUE"""),"Yes") -> Yes | S31: =IFERROR(__xludf.DUMMYFUNCTION("""COMPUTED_VALUE"""),"Yes") -> Yes | T31: =IFERROR(__xludf.DUMMYFUNCTION("""COMPUTED_VALUE"""),"Yes") -> Yes | U31: =IFERROR(__xludf.DUMMYFUNCTION("""COMPUTED_VALUE"""),"Yes") -> Yes | V31: =IFERROR(__xludf.DUMMYFUNCTION("""COMPUTED_VALUE"""),"Yes") -> Yes
